<?xml version="1.0"?>
<robot name="self_driving_car">
  <material name="blue">
    <color rgba="0 0 1 1"/>
  </material>
  <material name="black">
    <color rgba="0.1 0.1 0.1 1"/>
  </material>
  <material name="red">
    <color rgba="1 0 0 1"/>
  </material>

  <link name="base_link">
    <visual>
      <geometry>
        <box size="0.875 0.525 0.175"/>
      </geometry>
      <material name="blue"/>
    </visual>
    <collision>
      <geometry>
        <box size="0.875 0.525 0.175"/>
      </geometry>
    </collision>
    <inertial>
      <mass value="85.75"/>
      <inertia ixx="3.045" ixy="0" ixz="0" iyy="3.045" iyz="0" izz="3.045"/>
    </inertial>
  </link>

  <link name="front_left_wheel">
    <visual>
      <geometry>
        <cylinder length="0.035" radius="0.105"/>
      </geometry>
      <material name="black"/>
    </visual>
    <collision>
      <geometry>
        <cylinder length="0.035" radius="0.105"/>
      </geometry>
    </collision>
    <inertial>
      <mass value="1.29"/>
      <inertia ixx="0.0045" ixy="0" ixz="0" iyy="0.0045" iyz="0" izz="0.0045"/>
    </inertial>
  </link>

  <joint name="front_left_wheel_joint" type="continuous">
    <parent link="base_link"/>
    <child link="front_left_wheel"/>
    <origin xyz="0.2625 0.28 -0.0875" rpy="-1.5707 0 0"/>
    <axis xyz="0 0 1"/>
  </joint>

  <link name="front_right_wheel">
    <visual>
      <geometry>
        <cylinder length="0.035" radius="0.105"/>
      </geometry>
      <material name="black"/>
    </visual>
    <collision>
      <geometry>
        <cylinder length="0.035" radius="0.105"/>
      </geometry>
    </collision>
    <inertial>
      <mass value="1.29"/>
      <inertia ixx="0.0045" ixy="0" ixz="0" iyy="0.0045" iyz="0" izz="0.0045"/>
    </inertial>
  </link>

  <joint name="front_right_wheel_joint" type="continuous">
    <parent link="base_link"/>
    <child link="front_right_wheel"/>
    <origin xyz="0.2625 -0.28 -0.0875" rpy="-1.5707 0 0"/>
    <axis xyz="0 0 1"/>
  </joint>

  <link name="rear_left_wheel">
    <visual>
      <geometry>
        <cylinder length="0.035" radius="0.105"/>
      </geometry>
      <material name="black"/>
    </visual>
    <collision>
      <geometry>
        <cylinder length="0.035" radius="0.105"/>
      </geometry>
    </collision>
    <inertial>
      <mass value="1.29"/>
      <inertia ixx="0.0045" ixy="0" ixz="0" iyy="0.0045" iyz="0" izz="0.0045"/>
    </inertial>
  </link>

  <joint name="rear_left_wheel_joint" type="continuous">
    <parent link="base_link"/>
    <child link="rear_left_wheel"/>
    <origin xyz="-0.2625 0.28 -0.0875" rpy="-1.5707 0 0"/>
    <axis xyz="0 0 1"/>
  </joint>

  <link name="rear_right_wheel">
    <visual>
      <geometry>
        <cylinder length="0.035" radius="0.105"/>
      </geometry>
      <material name="black"/>
    </visual>
    <collision>
      <geometry>
        <cylinder length="0.035" radius="0.105"/>
      </geometry>
    </collision>
    <inertial>
      <mass value="1.29"/>
      <inertia ixx="0.0045" ixy="0" ixz="0" iyy="0.0045" iyz="0" izz="0.0045"/>
    </inertial>
  </link>

  <joint name="rear_right_wheel_joint" type="continuous">
    <parent link="base_link"/>
    <child link="rear_right_wheel"/>
    <origin xyz="-0.2625 -0.28 -0.0875" rpy="-1.5707 0 0"/>
    <axis xyz="0 0 1"/>
  </joint>

  <link name="camera_link">
    <visual>
      <geometry>
        <box size="0.035 0.035 0.035"/>
      </geometry>
      <material name="red"/>
    </visual>
    <collision>
      <geometry>
        <box size="0.035 0.035 0.035"/>
      </geometry>
    </collision>
    <inertial>
      <mass value="0.0137"/>
      <inertia ixx="0.00048" ixy="0" ixz="0" iyy="0.00048" iyz="0" izz="0.00048"/>
    </inertial>
  </link>

  <joint name="camera_joint" type="fixed">
    <parent link="base_link"/>
    <child link="camera_link"/>
    <origin xyz="0.42 0 0.0875" rpy="0 0 0"/>
  </joint>

  <gazebo reference="camera_link">
    <sensor type="camera" name="camera1">
      <update_rate>30.0</update_rate>
      <camera name="head">
        <horizontal_fov>1.3962634</horizontal_fov>
        <image>
          <width>800</width>
          <height>600</height>
          <format>R8G8B8</format>
        </image>
        <clip>
          <near>0.02</near>
          <far>300</far>
        </clip>
        <noise>
          <type>gaussian</type>
          <mean>0.0</mean>
          <stddev>0.007</stddev>
        </noise>
      </camera>
      <plugin name="camera_controller" filename="libgazebo_ros_camera.so">
        <alwaysOn>true</alwaysOn>
        <updateRate>0.0</updateRate>
        <cameraName>camera</cameraName>
        <imageTopicName>image_raw</imageTopicName>
        <cameraInfoTopicName>camera_info</cameraInfoTopicName>
        <frameName>camera_link</frameName>
        <hackBaseline>0.0245</hackBaseline>
        <distortionK1>0.0</distortionK1>
        <distortionK2>0.0</distortionK2>
        <distortionK3>0.0</distortionK3>
        <distortionT1>0.0</distortionT1>
        <distortionT2>0.0</distortionT2>
      </plugin>
    </sensor>
  </gazebo>

  <gazebo>
    <plugin name="differential_drive_controller" filename="libgazebo_ros_diff_drive.so">
      <legacyMode>false</legacyMode>
      <alwaysOn>true</alwaysOn>
      <updateRate>20</updateRate>
      <leftJoint>rear_left_wheel_joint</leftJoint>
      <rightJoint>rear_right_wheel_joint</rightJoint>
      <wheelSeparation>0.56</wheelSeparation>
      <wheelDiameter>0.21</wheelDiameter>
      <torque>2.8</torque>
      <commandTopic>cmd_vel</commandTopic>
      <odometryTopic>odom</odometryTopic>
      <odometryFrame>odom</odometryFrame>
      <robotBaseFrame>base_link</robotBaseFrame>
    </plugin>
  </gazebo>
</robot>

